<?xml version="1.0"?>
<robot name="twodofs">

    <!-- # Base and support  -->	
    <link name="world">
    </link> 
    <joint name="ground_fixed" type="fixed">
        <origin xyz="0 0 0" rpy="0 0 -1.57"/> 
        <parent link="world"/>
        <child link="ground"/>
        <axis xyz="0 0 0"/>
    </joint>
    <link name="ground">
        <inertial>
            <origin xyz="0 0 0" rpy="0 0 0"/>
            <mass value="1.0"/>
            <inertia ixx="0.1" iyy="0.1" izz="0.1" ixy="0" ixz="0" iyz="0"/>
        </inertial>
		<visual>
            <origin xyz="-0.1 -0.04 0" rpy="1.57 0 1.57"/>
            <geometry>
				<mesh filename="package://twodofs_description/meshes/twodofs/dae/Base2Dof_4040_m.dae"/>
            </geometry>	
        </visual>
		 <visual>
            <origin xyz="0 0.011 0.18" rpy="-1.57 -1.57 0"/>
            <geometry>
				<mesh filename="package://simplecube_description/meshes/qb_meshes/dae/qb_base_flange_m.dae" />
            </geometry>	
        </visual> 
		<visual>
            <origin xyz="0 0.044 0.1470" rpy="0 0 0"/>
            <geometry>
				<mesh filename="package://simplecube_description/meshes/qb_meshes/dae/qbmove_frame_m.dae" />
            </geometry>	
        </visual>
    </link>
    
	<!-- # First  -->
    <joint name="J1" type="revolute">
        <origin xyz="0 0.044 0.18" rpy="0 0 0"/>
        <parent link="ground"/>
        <child link="Link1"/>
		<limit effort="30" velocity="1.0" lower="-3.14" upper="3.14" />
        <axis xyz="0 0 1"/>
    </joint>
    
    <link name="Link1"> 
        <inertial>
            <origin xyz="0 0.085 0" rpy="0 0 0"/>
            <mass value="0.55"/>
            <inertia ixx="0.001" iyy="0.001" izz="0.001" ixy="0" ixz="0" iyz="0"/>
        </inertial>	
        <visual>
            <origin xyz="0 0.056 0" rpy="0 -1.57 -1.57"/>
            <geometry>
                <mesh filename="package://simplecube_description/meshes/qb_meshes/dae/qb_c_flange_m.dae" />
            </geometry>		
        </visual>
		<visual>
            <origin xyz="0 0.089 -0.033" rpy="0 0 0"/>
            <geometry>
				<mesh filename="package://simplecube_description/meshes/qb_meshes/dae/qbmove_frame_m.dae" />
            </geometry>		
        </visual>
    </link>  
	
	<!-- # Second -->
    <joint name="J2" type="revolute">
        <origin xyz="0 0.089 0" rpy="0 0 0"/>
        <parent link="Link1"/>
        <child link="Link2"/>
		<limit effort="30" velocity="1.0" lower="-3.14" upper="3.14" />
        <axis xyz="0 0 1"/>
    </joint>
    
    <link name="Link2"> 
        <inertial>
            <origin xyz="0 0.085 0" rpy="0 0 0"/>
            <mass value="0.55"/>
            <inertia ixx="0.001" iyy="0.001" izz="0.001" ixy="0" ixz="0" iyz="0"/>
        </inertial>	
        <visual>
            <origin xyz="0 0.056 0" rpy="0 -1.57 -1.57"/>
            <geometry>
                <mesh filename="package://simplecube_description/meshes/qb_meshes/dae/qb_c_flange_m.dae" />
            </geometry>		
        </visual>
		<visual>
            <origin xyz="0 0.089 -0.033" rpy="0 0 0"/>
            <geometry>
				<mesh filename="package://simplecube_description/meshes/qb_meshes/dae/qbmove_frame_m.dae" />
            </geometry>	
        </visual>
    </link>  

	<!-- # End effector -->
    <joint name="EE" type="fixed">
        <origin xyz="0 0.1220 0" rpy="0 0 0"/>
        <parent link="Link2"/>
        <child link="Tip"/>
        <axis xyz="0 0 1"/>
    </joint>
	<link name="Tip"> 
	</link> 
	


    <gazebo>
        <self_collide>1</self_collide>
    </gazebo>

<!--     <gazebo>
        <plugin name="advanced_vsa_j1" filename="libadvanced_plugin.so">
            <joint>J1</joint>
            <pub_eltau>false</pub_eltau>
            <pub_state>false</pub_state>
            <sub_ext_tau>false</sub_ext_tau>
        </plugin>
    </gazebo>
    <gazebo>
        <plugin name="advanced_vsa_j2" filename="libadvanced_plugin.so">
            <joint>J2</joint>
            <pub_eltau>false</pub_eltau>
            <pub_state>false</pub_state>
            <sub_ext_tau>false</sub_ext_tau>
        </plugin>
    </gazebo> -->

    <!-- Legend for the libcompliant_plugin.so custom plugin 
    
        # Types of actuators: rigid, sea, qbMove, bavs, fsj
        # If qbMove and bavs selected the control_type can be chosen as: [0,1,2]
        #      - [0] -> references are directly the motor positions
        #      - [1] -> references are used as equilibirium position and preset
        #      - [2] -> references are again used directly as motor positions, but the topics' names are taken from the motors_plugin (TODO!)
        # The other types does not require a control_type selected, but the tag should be inserted anyway
        #
        # The three other tags enable the generation and publication of additional topics: the elastic topic publisher, the state publisher and 
        #      enable the subscription to external torque topic

    -->
    <gazebo>
        <plugin name="advanced_vsa_j1" filename="libcompliant_plugin.so">
            <joint>J1</joint>
            <actuator_type>qbMove</actuator_type>         
            <control_type>1</control_type>              
            <pub_eltau>false</pub_eltau>                 
            <pub_state>true</pub_state>                 
            <sub_ext_tau>false</sub_ext_tau>             
        </plugin>                                       
    </gazebo>
    <gazebo>
        <plugin name="advanced_vsa_j2" filename="libcompliant_plugin.so">
            <joint>J2</joint>
            <actuator_type>qbMove</actuator_type>
            <control_type>1</control_type>
            <pub_eltau>false</pub_eltau>
            <pub_state>true</pub_state>
            <sub_ext_tau>false</sub_ext_tau>
        </plugin>
    </gazebo>

</robot>
